Workbook

Sheet Executive Dashboard
B2: 🛠️ Machine Spare Part Strategic Control Dashboard
B5: MC Group | C5: Risk Zone | D5: Items Count | E5: Inventory Value (THB) | F5: Reorder Items | H5: 📊 สรุปจำนวนชิ้นส่วนแยกตามระดับความสำคัญ (Machine Criticality)
B6: Forming | C6: 🔴 วิกฤต! (ของหมด) | D6: =COUNTIF('Master Data'!$W$2:$W$89, C6) -> 73 | E6: =SUMIF('Master Data'!$W$2:$W$89, C6, 'Master Data'!$U$2:$U$89) -> 0 | F6: =COUNTIFS('Master Data'!$W$2:$W$89,C6,'Master Data'!$V$2:$V$89, "ควรสั่งซื้อ") -> 73 | G6: =COUNTIFS('Master Data'!$B$2:$B$74,B6,'Master Data'!$W$2:$W$89,C6,'Master Data'!$V$2:$V$74, "*ควรสั่งซื้อ*") -> #VALUE! | H6: Criticality Score | I6: จำนวนอะไหล่ (รายการ)
C7: 🟡 ควรสั่งซื้อ (ต่ำกว่า ROP) | D7: =COUNTIF('Master Data'!$W$2:$W$89, C7) -> 9 | E7: =SUMIF('Master Data'!$W$2:$W$89, C7, 'Master Data'!$U$2:$U$89) -> 9000 | F7: =COUNTIFS('Master Data'!$W$2:$W$89,C7,'Master Data'!$V$2:$V$89, "ควรสั่งซื้อ") -> 9 | G7: =SUM(COUNTIFS('Master Data'!$B$2:$B$74, "Forming", 'Master Data'!$V$2:$V$74, "*วิกฤต*"), COUNTIFS('Master Data'!$B$2:$B$74, "Forming", 'Master Data'!$V$2:$V$74, "*ควรสั่งซื้อ*")) -> 40 | H7: 9 | I7: =COUNTIF('Master Data'!X2:X89, 9) -> 39
C8: 🟢 ปกติ | D8: =COUNTIF('Master Data'!$W$2:$W$89, C8) -> 6 | E8: =SUMIF('Master Data'!$W$2:$W$89, C8, 'Master Data'!$U$2:$U$89) -> 0 | F8: =COUNTIFS('Master Data'!$W$2:$W$89,C8,'Master Data'!$V$2:$V$89, "ควรสั่งซื้อ") -> 0 | H8: 6 | I8: =COUNTIF('Master Data'!X2:X89, 6) -> 47
C9: Total | D9: =SUM(D6:D8) -> 88 | E9: =SUM(E6:E8) -> 9000 | F9: =SUM(F6:F8) -> 82 | H9: 3 | I9: =COUNTIF('Master Data'!X2:X89, 3) -> 2
C23: ⚠️ รายการแจ้งเตือนชิ้นส่วนวิกฤตต่ำกว่า ROP และจุดสั่งซื้อที่ต้องดำเนินการทันที
C24: Part Code | D24: Part Name | E24: MC Group | F24: Min Stock | G24: ROP | H24: Current Stock | I24: Status Alert | J24: Criticality Score
C25: ='Master Data'!H2 -> PT-01 | D25: ='Master Data'!I2 -> Hydraulic pump | E25: ='Master Data'!B2 -> Forming | F25: ='Master Data'!Q2 -> 1 | G25: ='Master Data'!S2 -> 2 | H25: ='Master Data'!T2 -> 0 | I25: ='Master Data'!W2 -> 🔴 วิกฤต! (ของหมด) | J25: ='Master Data'!X2 -> 6
C26: ='Master Data'!H3 -> PT-02 | D26: ='Master Data'!I3 -> Filter | E26: ='Master Data'!B3 -> Forming | F26: ='Master Data'!Q3 -> 1 | G26: ='Master Data'!S3 -> 2 | H26: ='Master Data'!T3 -> 0 | I26: ='Master Data'!W3 -> 🔴 วิกฤต! (ของหมด) | J26: ='Master Data'!X3 -> 6
C27: ='Master Data'!H4 -> PT-03 | D27: ='Master Data'!I4 -> Oil Mirror | E27: ='Master Data'!B4 -> Forming | F27: ='Master Data'!Q4 -> 1 | G27: ='Master Data'!S4 -> 2 | H27: ='Master Data'!T4 -> 0 | I27: ='Master Data'!W4 -> 🔴 วิกฤต! (ของหมด) | J27: ='Master Data'!X4 -> 6
C28: ='Master Data'!H5 -> PT-04 | D28: ='Master Data'!I5 -> Solenoid Valve releasing cylinder upper | E28: ='Master Data'!B5 -> Forming | F28: ='Master Data'!Q5 -> 1 | G28: ='Master Data'!S5 -> 2 | H28: ='Master Data'!T5 -> 0 | I28: ='Master Data'!W5 -> 🔴 วิกฤต! (ของหมด) | J28: ='Master Data'!X5 -> 6
C29: ='Master Data'!H6 -> PT-05 | D29: ='Master Data'!I6 -> Solenoid Valve Main Cylinder | E29: ='Master Data'!B6 -> Forming | F29: ='Master Data'!Q6 -> 1 | G29: ='Master Data'!S6 -> 2 | H29: ='Master Data'!T6 -> 1 | I29: ='Master Data'!W6 -> 🟡 ควรสั่งซื้อ (ต่ำกว่า ROP) | J29: ='Master Data'!X6 -> 6
C30: ='Master Data'!H7 -> PT-06 | D30: ='Master Data'!I7 -> Solenoid Valve Mold Move in Cylinder | E30: ='Master Data'!B7 -> Forming | F30: ='Master Data'!Q7 -> 1 | G30: ='Master Data'!S7 -> 2 | H30: ='Master Data'!T7 -> 1 | I30: ='Master Data'!W7 -> 🟡 ควรสั่งซื้อ (ต่ำกว่า ROP) | J30: ='Master Data'!X7 -> 6
C31: ='Master Data'!H8 -> PT-07 | D31: ='Master Data'!I8 -> Counterbalance Valve | E31: ='Master Data'!B8 -> Forming | F31: ='Master Data'!Q8 -> 1 | G31: ='Master Data'!S8 -> 2 | H31: ='Master Data'!T8 -> 0 | I31: ='Master Data'!W8 -> 🔴 วิกฤต! (ของหมด) | J31: ='Master Data'!X8 -> 6
C32: ='Master Data'!H9 -> PT-08 | D32: ='Master Data'!I9 -> Counterbalance Valve | E32: ='Master Data'!B9 -> Forming | F32: ='Master Data'!Q9 -> 1 | G32: ='Master Data'!S9 -> 2 | H32: ='Master Data'!T9 -> 0 | I32: ='Master Data'!W9 -> 🔴 วิกฤต! (ของหมด) | J32: ='Master Data'!X9 -> 6
C33: ='Master Data'!H10 -> PT-09 | D33: ='Master Data'!I10 -> Proportion Pressure & Flow Compound Valve | E33: ='Master Data'!B10 -> Forming | F33: ='Master Data'!Q10 -> 1 | G33: ='Master Data'!S10 -> 2 | H33: ='Master Data'!T10 -> 0 | I33: ='Master Data'!W10 -> 🔴 วิกฤต! (ของหมด) | J33: ='Master Data'!X10 -> 6
C34: ='Master Data'!H11 -> PT-10 | D34: ='Master Data'!I11 -> Stop Valve | E34: ='Master Data'!B11 -> Forming | F34: ='Master Data'!Q11 -> 0 | G34: ='Master Data'!S11 -> 0 | H34: ='Master Data'!T11 -> 0 | I34: ='Master Data'!W11 -> 🔴 วิกฤต! (ของหมด) | J34: ='Master Data'!X11 -> 6
C35: ='Master Data'!H12 -> PT-11 | D35: ='Master Data'!I12 -> Wiper Seal | E35: ='Master Data'!B12 -> Forming | F35: ='Master Data'!Q12 -> 0 | G35: ='Master Data'!S12 -> 0 | H35: ='Master Data'!T12 -> 0 | I35: ='Master Data'!W12 -> 🔴 วิกฤต! (ของหมด) | J35: ='Master Data'!X12 -> 6
C36: ='Master Data'!H13 -> PT-12 | D36: ='Master Data'!I13 -> Spindel Seal | E36: ='Master Data'!B13 -> Forming | F36: ='Master Data'!Q13 -> 0 | G36: ='Master Data'!S13 -> 0 | H36: ='Master Data'!T13 -> 0 | I36: ='Master Data'!W13 -> 🔴 วิกฤต! (ของหมด) | J36: ='Master Data'!X13 -> 6
... C38: ='Master Data'!H15 -> PT-14 | D38: ='Master Data'!I15 -> O-Ring | E38: ='Master Data'!B15 -> Forming | F38: ='Master Data'!Q15 -> 0 | G38: ='Master Data'!S15 -> 0 | H38: ='Master Data'!T15 -> 0 | I38: ='Master Data'!W15 -> 🔴 วิกฤต! (ของหมด) | J38: ='Master Data'!X15 -> 3

Sheet Master Data
A1: Item | B1: MC Group | C1: MC Type | D1: MC Code | E1: Machine Name | F1: MC Common | G1: Location Use | H1: Part Code | I1: Part Name | J1: Machine Rank | K1: Brand/Maker | L1: Part Rank | M1: Unit | N1: Price Unit (Baht) | O1: Keeping Area | P1: Max Stock | Q1: Min Stock | R1: Safety Stock (Formula) | S1: ROP (Reorder Point) | T1: Current Stock | U1: Amount (Baht) | V1: Status Alert | W1: Risk Zone | X1: Machine Criticality Score | Y1: Owner (Responsibility) | Z1: Lead Time (Days) | AA1: Location Order | AB1: Remark
A2: 1 | B2: Forming | C2: Vacuum | D2: C16 | E2: 200 Ton | F2: All | G2: Main Hyd. | H2: PT-01 | I2: Hydraulic pump | J2: B | K2: TECO | L2: Medium | M2: PCS | N2: 0 | O2: AR-01 | P2: 2 | Q2: 1 | R2: =ROUND(Q2*0.5,0) -> 1 | S2: =Q2+R2 -> 2 | T2: =SUMIF('Stock In Log'!C:C, H2, 'Stock In Log'!D:D) - SUMIF('Stock Out Log'!C:C, H2, 'Stock Out Log'!D:D) -> 0 | U2: =N2*T2 -> 0 | V2: =IF(T2<=0,"ควรสั่งซื้อ", IF(T2<=S2,"ควรสั่งซื้อ","ปกติ")) -> ควรสั่งซื้อ | W2: =IF(T2<=0, "🔴 วิกฤต! (ของหมด)", IF(T2<=S2, "🟡 ควรสั่งซื้อ (ต่ำกว่า ROP)", "🟢 ปกติ")) -> 🔴 วิกฤต! (ของหมด) | X2: 6 | Y2: Maintenance Team | Z2: 0
A3: 2 | B3: Forming | C3: Vacuum | D3: B17 | E3: 200 Ton | F3: B14,B15,B16,B18,B19 | G3: Main Hyd. | H3: PT-02 | I3: Filter | J3: B | L3: Medium | M3: PCS | N3: 0 | O3: AR-02 | P3: 2 | Q3: 1 | R3: =ROUND(Q3*0.5,0) -> 1 | S3: =Q3+R3 -> 2 | T3: =SUMIF('Stock In Log'!C:C, H3, 'Stock In Log'!D:D) - SUMIF('Stock Out Log'!C:C, H3, 'Stock Out Log'!D:D) -> 0 | U3: =N3*T3 -> 0 | V3: =IF(T3<=0,"ควรสั่งซื้อ", IF(T3<=S3,"ควรสั่งซื้อ","ปกติ")) -> ควรสั่งซื้อ | W3: =IF(T3<=0, "🔴 วิกฤต! (ของหมด)", IF(T3<=S3, "🟡 ควรสั่งซื้อ (ต่ำกว่า ROP)", "🟢 ปกติ")) -> 🔴 วิกฤต! (ของหมด) | X3: 6 | Y3: Maintenance Team | Z3: 0
A4: 3 | B4: Forming | C4: Vacuum | D4: B17 | E4: 200 Ton | F4: B18,B19 | G4: Main Hyd. | H4: PT-03 | I4: Oil Mirror | J4: B | L4: Medium | M4: PCS | N4: 0 | O4: AR-03 | P4: 2 | Q4: 1 | R4: =ROUND(Q4*0.5,0) -> 1 | S4: =Q4+R4 -> 2 | T4: =SUMIF('Stock In Log'!C:C, H4, 'Stock In Log'!D:D) - SUMIF('Stock Out Log'!C:C, H4, 'Stock Out Log'!D:D) -> 0 | U4: =N4*T4 -> 0 | V4: =IF(T4<=0,"ควรสั่งซื้อ", IF(T4<=S4,"ควรสั่งซื้อ","ปกติ")) -> ควรสั่งซื้อ | W4: =IF(T4<=0, "🔴 วิกฤต! (ของหมด)", IF(T4<=S4, "🟡 ควรสั่งซื้อ (ต่ำกว่า ROP)", "🟢 ปกติ")) -> 🔴 วิกฤต! (ของหมด) | X4: 6 | Y4: Maintenance Team | Z4: 0
A5: 4 | B5: Forming | C5: Vacuum | D5: - | G5: Main Hyd. | H5: PT-04 | I5: Solenoid Valve releasing cylinder upper | J5: B | K5: Yuken | L5: Medium | M5: PCS | N5: 0 | O5: AR-04 | P5: 2 | Q5: 1 | R5: =ROUND(Q5*0.5,0) -> 1 | S5: =Q5+R5 -> 2 | T5: =SUMIF('Stock In Log'!C:C, H5, 'Stock In Log'!D:D) - SUMIF('Stock Out Log'!C:C, H5, 'Stock Out Log'!D:D) -> 0 | U5: =N5*T5 -> 0 | V5: =IF(T5<=0,"ควรสั่งซื้อ", IF(T5<=S5,"ควรสั่งซื้อ","ปกติ")) -> ควรสั่งซื้อ | W5: =IF(T5<=0, "🔴 วิกฤต! (ของหมด)", IF(T5<=S5, "🟡 ควรสั่งซื้อ (ต่ำกว่า ROP)", "🟢 ปกติ")) -> 🔴 วิกฤต! (ของหมด) | X5: 6 | Y5: Maintenance Team | Z5: 7 | AA5: Local | AB5: Local
A6: 5 | B6: Forming | C6: Vacuum | D6: - | G6: Main Hyd. | H6: PT-05 | I6: Solenoid Valve Main Cylinder | J6: B | K6: Yuken | L6: Medium | M6: PCS | N6: 0 | O6: AR-05 | P6: 2 | Q6: 1 | R6: =ROUND(Q6*0.5,0) -> 1 | S6: =Q6+R6 -> 2 | T6: =SUMIF('Stock In Log'!C:C, H6, 'Stock In Log'!D:D) - SUMIF('Stock Out Log'!C:C, H6, 'Stock Out Log'!D:D) -> 1 | U6: =N6*T6 -> 0 | V6: =IF(T6<=0,"ควรสั่งซื้อ", IF(T6<=S6,"ควรสั่งซื้อ","ปกติ")) -> ควรสั่งซื้อ | W6: =IF(T6<=0, "🔴 วิกฤต! (ของหมด)", IF(T6<=S6, "🟡 ควรสั่งซื้อ (ต่ำกว่า ROP)", "🟢 ปกติ")) -> 🟡 ควรสั่งซื้อ (ต่ำกว่า ROP) | X6: 6 | Y6: Maintenance Team | Z6: 7 | AA6: Local | AB6: Local
A7: 6 | B7: Forming | C7: Vacuum | D7: - | G7: Main Hyd. | H7: PT-06 | I7: Solenoid Valve Mold Move in Cylinder | J7: B | K7: Yuken | L7: Medium | M7: PCS | N7: 0 | O7: AR-06 | P7: 2 | Q7: 1 | R7: =ROUND(Q7*0.5,0) -> 1 | S7: =Q7+R7 -> 2 | T7: =SUMIF('Stock In Log'!C:C, H7, 'Stock In Log'!D:D) - SUMIF('Stock Out Log'!C:C, H7, 'Stock Out Log'!D:D) -> 1 | U7: =N7*T7 -> 0 | V7: =IF(T7<=0,"ควรสั่งซื้อ", IF(T7<=S7,"ควรสั่งซื้อ","ปกติ")) -> ควรสั่งซื้อ | W7: =IF(T7<=0, "🔴 วิกฤต! (ของหมด)", IF(T7<=S7, "🟡 ควรสั่งซื้อ (ต่ำกว่า ROP)", "🟢 ปกติ")) -> 🟡 ควรสั่งซื้อ (ต่ำกว่า ROP) | X7: 6 | Y7: Maintenance Team | Z7: 7 | AA7: Local | AB7: Local
A8: 7 | B8: Forming | C8: Vacuum | D8: - | G8: Main Hyd. | H8: PT-07 | I8: Counterbalance Valve | J8: B | K8: Yuken | L8: Critical | M8: PCS | N8: 0 | O8: AR-07 | P8: 2 | Q8: 1 | R8: =ROUND(Q8*0.5,0) -> 1 | S8: =Q8+R8 -> 2 | T8: =SUMIF('Stock In Log'!C:C, H8, 'Stock In Log'!D:D) - SUMIF('Stock Out Log'!C:C, H8, 'Stock Out Log'!D:D) -> 0 | U8: =N8*T8 -> 0 | V8: =IF(T8<=0,"ควรสั่งซื้อ", IF(T8<=S8,"ควรสั่งซื้อ","ปกติ")) -> ควรสั่งซื้อ | W8: =IF(T8<=0, "🔴 วิกฤต! (ของหมด)", IF(T8<=S8, "🟡 ควรสั่งซื้อ (ต่ำกว่า ROP)", "🟢 ปกติ")) -> 🔴 วิกฤต! (ของหมด) | X8: 6 | Y8: Maintenance Team | Z8: 7 | AA8: Local | AB8: Local
A9: 8 | B9: Forming | C9: Vacuum | D9: - | G9: Main Hyd. | H9: PT-08 | I9: Counterbalance Valve | J9: B | K9: Yuken | L9: Critical | M9: PCS | N9: 0 | O9: AR-08 | P9: 2 | Q9: 1 | R9: =ROUND(Q9*0.5,0) -> 1 | S9: =Q9+R9 -> 2 | T9: =SUMIF('Stock In Log'!C:C, H9, 'Stock In Log'!D:D) - SUMIF('Stock Out Log'!C:C, H9, 'Stock Out Log'!D:D) -> 0 | U9: =N9*T9 -> 0 | V9: =IF(T9<=0,"ควรสั่งซื้อ", IF(T9<=S9,"ควรสั่งซื้อ","ปกติ")) -> ควรสั่งซื้อ | W9: =IF(T9<=0, "🔴 วิกฤต! (ของหมด)", IF(T9<=S9, "🟡 ควรสั่งซื้อ (ต่ำกว่า ROP)", "🟢 ปกติ")) -> 🔴 วิกฤต! (ของหมด) | X9: 6 | Y9: Maintenance Team | Z9: 7 | AA9: Local | AB9: Local
A10: 9 | B10: Forming | C10: Vacuum | D10: - | G10: Main Hyd. | H10: PT-09 | I10: Proportion Pressure & Flow Compound Valve | J10: B | K10: Yuken | L10: Low | M10: PCS | N10: 31000 | O10: AR-09 | P10: 2 | Q10: 1 | R10: =ROUND(Q10*0.5,0) -> 1 | S10: =Q10+R10 -> 2 | T10: =SUMIF('Stock In Log'!C:C, H10, 'Stock In Log'!D:D) - SUMIF('Stock Out Log'!C:C, H10, 'Stock Out Log'!D:D) -> 0 | U10: =N10*T10 -> 0 | V10: =IF(T10<=0,"ควรสั่งซื้อ", IF(T10<=S10,"ควรสั่งซื้อ","ปกติ")) -> ควรสั่งซื้อ | W10: =IF(T10<=0, "🔴 วิกฤต! (ของหมด)", IF(T10<=S10, "🟡 ควรสั่งซื้อ (ต่ำกว่า ROP)", "🟢 ปกติ")) -> 🔴 วิกฤต! (ของหมด) | X10: 6 | Y10: Maintenance Team | Z10: 7 | AA10: Local | AB10: Local
A11: 10 | B11: Forming | C11: Vacuum | D11: - | G11: Main Hyd. | H11: PT-10 | I11: Stop Valve | J11: B | K11: Yuken | L11: Low | M11: PCS | N11: 0 | O11: AR-10 | P11: 0 | Q11: 0 | R11: =ROUND(Q11*0.5,0) -> 0 | S11: =Q11+R11 -> 0 | T11: =SUMIF('Stock In Log'!C:C, H11, 'Stock In Log'!D:D) - SUMIF('Stock Out Log'!C:C, H11, 'Stock Out Log'!D:D) -> 0 | U11: =N11*T11 -> 0 | V11: =IF(T11<=0,"ควรสั่งซื้อ", IF(T11<=S11,"ควรสั่งซื้อ","ปกติ")) -> ควรสั่งซื้อ | W11: =IF(T11<=0, "🔴 วิกฤต! (ของหมด)", IF(T11<=S11, "🟡 ควรสั่งซื้อ (ต่ำกว่า ROP)", "🟢 ปกติ")) -> 🔴 วิกฤต! (ของหมด) | X11: 6 | Y11: Maintenance Team | Z11: 0
A12: 11 | B12: Forming | C12: Vacuum | D12: - | G12: Cylinder Hyd | H12: PT-11 | I12: Wiper Seal | J12: B | M12: PCS | N12: 0 | O12: AR-11 | P12: 0 | Q12: 0 | R12: =ROUND(Q12*0.5,0) -> 0 | S12: =Q12+R12 -> 0 | T12: =SUMIF('Stock In Log'!C:C, H12, 'Stock In Log'!D:D) - SUMIF('Stock Out Log'!C:C, H12, 'Stock Out Log'!D:D) -> 0 | U12: =N12*T12 -> 0 | V12: =IF(T12<=0,"ควรสั่งซื้อ", IF(T12<=S12,"ควรสั่งซื้อ","ปกติ")) -> ควรสั่งซื้อ | W12: =IF(T12<=0, "🔴 วิกฤต! (ของหมด)", IF(T12<=S12, "🟡 ควรสั่งซื้อ (ต่ำกว่า ROP)", "🟢 ปกติ")) -> 🔴 วิกฤต! (ของหมด) | X12: 6 | Y12: Maintenance Team | Z12: 0
A13: 12 | B13: Forming | C13: Vacuum | D13: - | G13: Cylinder Hyd | H13: PT-12 | I13: Spindel Seal | J13: B | M13: PCS | N13: 0 | O13: AR-12 | P13: 0 | Q13: 0 | R13: =ROUND(Q13*0.5,0) -> 0 | S13: =Q13+R13 -> 0 | T13: =SUMIF('Stock In Log'!C:C, H13, 'Stock In Log'!D:D) - SUMIF('Stock Out Log'!C:C, H13, 'Stock Out Log'!D:D) -> 0 | U13: =N13*T13 -> 0 | V13: =IF(T13<=0,"ควรสั่งซื้อ", IF(T13<=S13,"ควรสั่งซื้อ","ปกติ")) -> ควรสั่งซื้อ | W13: =IF(T13<=0, "🔴 วิกฤต! (ของหมด)", IF(T13<=S13, "🟡 ควรสั่งซื้อ (ต่ำกว่า ROP)", "🟢 ปกติ")) -> 🔴 วิกฤต! (ของหมด) | X13: 6 | Y13: Maintenance Team | Z13: 0
A14: 13 | B14: Forming | C14: Vacuum | D14: - | G14: Cylinder Hyd | H14: PT-13 | I14: O-Ring | J14: B | M14: PCS | N14: 0 | O14: AR-13 | P14: 0 | Q14: 0 | R14: =ROUND(Q14*0.5,0) -> 0 | S14: =Q14+R14 -> 0 | T14: =SUMIF('Stock In Log'!C:C, H14, 'Stock In Log'!D:D) - SUMIF('Stock Out Log'!C:C, H14, 'Stock Out Log'!D:D) -> 0 | U14: =N14*T14 -> 0 | V14: =IF(T14<=0,"ควรสั่งซื้อ", IF(T14<=S14,"ควรสั่งซื้อ","ปกติ")) -> ควรสั่งซื้อ | W14: =IF(T14<=0, "🔴 วิกฤต! (ของหมด)", IF(T14<=S14, "🟡 ควรสั่งซื้อ (ต่ำกว่า ROP)", "🟢 ปกติ")) -> 🔴 วิกฤต! (ของหมด) | X14: 6 | Y14: Maintenance Team | Z14: 0
A15: 14 | B15: Forming | C15: Vacuum | D15: - | G15: Cylinder Hyd | H15: PT-14 | I15: O-Ring | N15: 0 | O15: AR-14 | P15: 0 | Q15: 0 | R15: =ROUND(Q15*0.5,0) -> 0 | S15: =Q15+R15 -> 0 | T15: =SUMIF('Stock In Log'!C:C, H15, 'Stock In Log'!D:D) - SUMIF('Stock Out Log'!C:C, H15, 'Stock Out Log'!D:D) -> 0 | U15: =N15*T15 -> 0 | V15: =IF(T15<=0,"ควรสั่งซื้อ", IF(T15<=S15,"ควรสั่งซื้อ","ปกติ")) -> ควรสั่งซื้อ | W15: =IF(T15<=0, "🔴 วิกฤต! (ของหมด)", IF(T15<=S15, "🟡 ควรสั่งซื้อ (ต่ำกว่า ROP)", "🟢 ปกติ")) -> 🔴 วิกฤต! (ของหมด) | X15: 3 | Y15: Store Keeper | Z15: 0
A16: 15 | B16: Forming | C16: Vacuum | D16: - | G16: Vacuum Unit | H16: PT-15 | I16: Vacuum pump Motor | J16: B | M16: PCS | N16: 0 | O16: AR-15 | P16: 0 | Q16: 0 | R16: =ROUND(Q16*0.5,0) -> 0 | S16: =Q16+R16 -> 0 | T16: =SUMIF('Stock In Log'!C:C, H16, 'Stock In Log'!D:D) - SUMIF('Stock Out Log'!C:C, H16, 'Stock Out Log'!D:D) -> 0 | U16: =N16*T16 -> 0 | V16: =IF(T16<=0,"ควรสั่งซื้อ", IF(T16<=S16,"ควรสั่งซื้อ","ปกติ")) -> ควรสั่งซื้อ | W16: =IF(T16<=0, "🔴 วิกฤต! (ของหมด)", IF(T16<=S16, "🟡 ควรสั่งซื้อ (ต่ำกว่า ROP)", "🟢 ปกติ")) -> 🔴 วิกฤต! (ของหมด) | X16: 6 | Y16: Maintenance Team | Z16: 0
A17: 16 | B17: Forming | C17: Vacuum | D17: - | G17: Vacuum Unit | H17: PT-16 | I17: Solenoid Valve | J17: B | K17: Mindman | M17: PCS | N17: 0 | O17: AR-16 | P17: 0 | Q17: 0 | R17: =ROUND(Q17*0.5,0) -> 0 | S17: =Q17+R17 -> 0 | T17: =SUMIF('Stock In Log'!C:C, H17, 'Stock In Log'!D:D) - SUMIF('Stock Out Log'!C:C, H17, 'Stock Out Log'!D:D) -> 0 | U17: =N17*T17 -> 0 | V17: =IF(T17<=0,"ควรสั่งซื้อ", IF(T17<=S17,"ควรสั่งซื้อ","ปกติ")) -> ควรสั่งซื้อ | W17: =IF(T17<=0, "🔴 วิกฤต! (ของหมด)", IF(T17<=S17, "🟡 ควรสั่งซื้อ (ต่ำกว่า ROP)", "🟢 ปกติ")) -> 🔴 วิกฤต! (ของหมด) | X17: 6 | Y17: Maintenance Team | Z17: 0
A18: 17 | B18: Forming | C18: Vacuum | D18: - | G18: Vacuum Unit | H18: PT-17 | I18: Air Switch | J18: B | M18: PCS | N18: 0 | O18: AR-17 | P18: 0 | Q18: 0 | R18: =ROUND(Q18*0.5,0) -> 0 | S18: =Q18+R18 -> 0 | T18: =SUMIF('Stock In Log'!C:C, H18, 'Stock In Log'!D:D) - SUMIF('Stock Out Log'!C:C, H18, 'Stock Out Log'!D:D) -> 0 | U18: =N18*T18 -> 0 | V18: =IF(T18<=0,"ควรสั่งซื้อ", IF(T18<=S18,"ควรสั่งซื้อ","ปกติ")) -> ควรสั่งซื้อ | W18: =IF(T18<=0, "🔴 วิกฤต! (ของหมด)", IF(T18<=S18, "🟡 ควรสั่งซื้อ (ต่ำกว่า ROP)", "🟢 ปกติ")) -> 🔴 วิกฤต! (ของหมด) | X18: 6 | Y18: Maintenance Team | Z18: 0
A19: 18 | B19: Forming | C19: Vacuum | D19: - | G19: Vacuum Unit | H19: PT-18 | I19: Pressure Switch | J19: B | M19: PCS | N19: 0 | O19: AR-18 | P19: 0 | Q19: 0 | R19: =ROUND(Q19*0.5,0) -> 0 | S19: =Q19+R19 -> 0 | T19: =SUMIF('Stock In Log'!C:C, H19, 'Stock In Log'!D:D) - SUMIF('Stock Out Log'!C:C, H19, 'Stock Out Log'!D:D) -> 0 | U19: =N19*T19 -> 0 | V19: =IF(T19<=0,"ควรสั่งซื้อ", IF(T19<=S19,"ควรสั่งซื้อ","ปกติ")) -> ควรสั่งซื้อ | W19: =IF(T19<=0, "🔴 วิกฤต! (ของหมด)", IF(T19<=S19, "🟡 ควรสั่งซื้อ (ต่ำกว่า ROP)", "🟢 ปกติ")) -> 🔴 วิกฤต! (ของหมด) | X19: 6 | Y19: Maintenance Team | Z19: 0
A20: 19 | B20: Forming | C20: Vacuum | D20: - | G20: Electrical System | H20: PT-19 | I20: Breaker Main | J20: B | K20: Fuji | M20: PCS | N20: 0 | O20: AR-19 | P20: 0 | Q20: 0 | R20: =ROUND(Q20*0.5,0) -> 0 | S20: =Q20+R20 -> 0 | T20: =SUMIF('Stock In Log'!C:C, H20, 'Stock In Log'!D:D) - SUMIF('Stock Out Log'!C:C, H20, 'Stock Out Log'!D:D) -> 0 | U20: =N20*T20 -> 0 | V20: =IF(T20<=0,"ควรสั่งซื้อ", IF(T20<=S20,"ควรสั่งซื้อ","ปกติ")) -> ควรสั่งซื้อ | W20: =IF(T20<=0, "🔴 วิกฤต! (ของหมด)", IF(T20<=S20, "🟡 ควรสั่งซื้อ (ต่ำกว่า ROP)", "🟢 ปกติ")) -> 🔴 วิกฤต! (ของหมด) | X20: 6 | Y20: Maintenance Team | Z20: 0
A21: 20 | B21: Forming | C21: Vacuum | D21: - | G21: Electrical System | H21: PT-20 | I21: Breaker Heater | J21: B | K21: Fuji | M21: PCS | N21: 0 | O21: AR-20 | P21: 0 | Q21: 0 | R21: =ROUND(Q21*0.5,0) -> 0 | S21: =Q21+R21 -> 0 | T21: =SUMIF('Stock In Log'!C:C, H21, 'Stock In Log'!D:D) - SUMIF('Stock Out Log'!C:C, H21, 'Stock Out Log'!D:D) -> 0 | U21: =N21*T21 -> 0 | V21: =IF(T21<=0,"ควรสั่งซื้อ", IF(T21<=S21,"ควรสั่งซื้อ","ปกติ")) -> ควรสั่งซื้อ | W21: =IF(T21<=0, "🔴 วิกฤต! (ของหมด)", IF(T21<=S21, "🟡 ควรสั่งซื้อ (ต่ำกว่า ROP)", "🟢 ปกติ")) -> 🔴 วิกฤต! (ของหมด) | X21: 6 | Y21: Maintenance Team | Z21: 0
A22: 21 | B22: Forming | C22: Vacuum | D22: - | G22: Electrical System | H22: PT-21 | I22: Power Supply | J22: B | K22: Omron | M22: PCS | N22: 0 | O22: AR-21 | P22: 0 | Q22: 0 | R22: =ROUND(Q22*0.5,0) -> 0 | S22: =Q22+R22 -> 0 | T22: =SUMIF('Stock In Log'!C:C, H22, 'Stock In Log'!D:D) - SUMIF('Stock Out Log'!C:C, H22, 'Stock Out Log'!D:D) -> 0 | U22: =N22*T22 -> 0 | V22: =IF(T22<=0,"ควรสั่งซื้อ", IF(T22<=S22,"ควรสั่งซื้อ","ปกติ")) -> ควรสั่งซื้อ | W22: =IF(T22<=0, "🔴 วิกฤต! (ของหมด)", IF(T22<=S22, "🟡 ควรสั่งซื้อ (ต่ำกว่า ROP)", "🟢 ปกติ")) -> 🔴 วิกฤต! (ของหมด) | X22: 6 | Y22: Maintenance Team | Z22: 0
A23: 22 | B23: Forming | C23: Vacuum | D23: - | G23: Electrical System | H23: PT-22 | I23: Temperature Controller | J23: B | K23: Omron | M23: PCS | N23: 0 | O23: AR-22 | P23: 5 | Q23: 3 | R23: =ROUND(Q23*0.5,0) -> 2 | S23: =Q23+R23 -> 5 | T23: =SUMIF('Stock In Log'!C:C, H23, 'Stock In Log'!D:D) - SUMIF('Stock Out Log'!C:C, H23, 'Stock Out Log'!D:D) -> 7 | U23: =N23*T23 -> 0 | V23: =IF(T23<=0,"ควรสั่งซื้อ", IF(T23<=S23,"ควรสั่งซื้อ","ปกติ")) -> ปกติ | W23: =IF(T23<=0, "🔴 วิกฤต! (ของหมด)", IF(T23<=S23, "🟡 ควรสั่งซื้อ (ต่ำกว่า ROP)", "🟢 ปกติ")) -> 🟢 ปกติ | X23: 6 | Y23: Maintenance Team | Z23: 0 | AA23: oversee
A24: 23 | B24: Forming | C24: Vacuum | D24: - | G24: Electrical System | H24: PT-23 | I24: Magnetic Contactor Motor pump | J24: B | K24: Fuji | M24: PCS | N24: 0 | O24: AR-23 | P24: 0 | Q24: 0 | R24: =ROUND(Q24*0.5,0) -> 0 | S24: =Q24+R24 -> 0 | T24: =SUMIF('Stock In Log'!C:C, H24, 'Stock In Log'!D:D) - SUMIF('Stock Out Log'!C:C, H24, 'Stock Out Log'!D:D) -> 2 | U24: =N24*T24 -> 0 | V24: =IF(T24<=0,"ควรสั่งซื้อ", IF(T24<=S24,"ควรสั่งซื้อ","ปกติ")) -> ปกติ | W24: =IF(T24<=0, "🔴 วิกฤต! (ของหมด)", IF(T24<=S24, "🟡 ควรสั่งซื้อ (ต่ำกว่า ROP)", "🟢 ปกติ")) -> 🟢 ปกติ | X24: 6 | Y24: Maintenance Team | Z24: 0 | AA24: oversee
A25: 24 | B25: Forming | C25: Vacuum | D25: - | G25: Electrical System | H25: PT-24 | I25: Magnetic Switch Heater | J25: B | K25: Fuji | M25: PCS | N25: 0 | O25: AR-24 | P25: 0 | Q25: 0 | R25: =ROUND(Q25*0.5,0) -> 0 | S25: =Q25+R25 -> 0 | T25: =SUMIF('Stock In Log'!C:C, H25, 'Stock In Log'!D:D) - SUMIF('Stock Out Log'!C:C, H25, 'Stock Out Log'!D:D) -> 2 | U25: =N25*T25 -> 0 | V25: =IF(T25<=0,"ควรสั่งซื้อ", IF(T25<=S25,"ควรสั่งซื้อ","ปกติ")) -> ปกติ | W25: =IF(T25<=0, "🔴 วิกฤต! (ของหมด)", IF(T25<=S25, "🟡 ควรสั่งซื้อ (ต่ำกว่า ROP)", "🟢 ปกติ")) -> 🟢 ปกติ | X25: 6 | Y25: Maintenance Team | Z25: 0 | AA25: oversee
A26: 25 | B26: Forming | C26: Vacuum | D26: - | F26: All | G26: Electrical System | H26: PT-25 | I26: Overload Motor pump Hyd | J26: B | K26: Fuji | M26: PCS | N26: 0 | O26: AR-25 | P26: 5 | Q26: 3 | R26: =ROUND(Q26*0.5,0) -> 2 | S26: =Q26+R26 -> 5 | T26: =SUMIF('Stock In Log'!C:C, H26, 'Stock In Log'!D:D) - SUMIF('Stock Out Log'!C:C, H26, 'Stock Out Log'!D:D) -> 6 | U26: =N26*T26 -> 0 | V26: =IF(T26<=0,"ควรสั่งซื้อ", IF(T26<=S26,"ควรสั่งซื้อ","ปกติ")) -> ปกติ | W26: =IF(T26<=0, "🔴 วิกฤต! (ของหมด)", IF(T26<=S26, "🟡 ควรสั่งซื้อ (ต่ำกว่า ROP)", "🟢 ปกติ")) -> 🟢 ปกติ | X26: 6 | Y26: Maintenance Team | Z26: 7 | AA26: oversee
A27: 26 | B27: Forming | C27: Vacuum | D27: - | F27: All | G27: Electrical System | H27: PT-26 | I27: Overload Motor Vacuum | J27: B | M27: PCS | N27: 0 | O27: AR-26 | P27: 4 | Q27: 2 | R27: =ROUND(Q27*0.5,0) -> 1 | S27: =Q27+R27 -> 3 | T27: =SUMIF('Stock In Log'!C:C, H27, 'Stock In Log'!D:D) - SUMIF('Stock Out Log'!C:C, H27, 'Stock Out Log'!D:D) -> 2 | U27: =N27*T27 -> 0 | V27: =IF(T27<=0,"ควรสั่งซื้อ", IF(T27<=S27,"ควรสั่งซื้อ","ปกติ")) -> ควรสั่งซื้อ | W27: =IF(T27<=0, "🔴 วิกฤต! (ของหมด)", IF(T27<=S27, "🟡 ควรสั่งซื้อ (ต่ำกว่า ROP)", "🟢 ปกติ")) -> 🟡 ควรสั่งซื้อ (ต่ำกว่า ROP) | X27: 6 | Y27: Maintenance Team | Z27: 7 | AA27: oversee
A28: 27 | B28: Forming | C28: Vacuum | D28: - | G28: Electrical System | H28: PT-27 | I28: Relay | J28: A | K28: Omron | M28: PCS | N28: 0 | O28: AR-27 | P28: 0 | Q28: 0 | R28: =ROUND(Q28*0.5,0) -> 0 | S28: =Q28+R28 -> 0 | T28: =SUMIF('Stock In Log'!C:C, H28, 'Stock In Log'!D:D) - SUMIF('Stock Out Log'!C:C, H28, 'Stock Out Log'!D:D) -> 0 | U28: =N28*T28 -> 0 | V28: =IF(T28<=0,"ควรสั่งซื้อ", IF(T28<=S28,"ควรสั่งซื้อ","ปกติ")) -> ควรสั่งซื้อ | W28: =IF(T28<=0, "🔴 วิกฤต! (ของหมด)", IF(T28<=S28, "🟡 ควรสั่งซื้อ (ต่ำกว่า ROP)", "🟢 ปกติ")) -> 🔴 วิกฤต! (ของหมด) | X28: 9 | Y28: Maintenance Team | Z28: 0
A29: 28 | B29: Forming | C29: Vacuum | D29: - | F29: A4-A7,B4-B7 | G29: Electrical System | H29: PT-28 | I29: PLC Controller | J29: A | K29: Omron | M29: PCS | N29: 0 | O29: AR-28 | P29: 0 | Q29: 0 | R29: =ROUND(Q29*0.5,0) -> 0 | S29: =Q29+R29 -> 0 | T29: =SUMIF('Stock In Log'!C:C, H29, 'Stock In Log'!D:D) - SUMIF('Stock Out Log'!C:C, H29, 'Stock Out Log'!D:D) -> 0 | U29: =N29*T29 -> 0 | V29: =IF(T29<=0,"ควรสั่งซื้อ", IF(T29<=S29,"ควรสั่งซื้อ","ปกติ")) -> ควรสั่งซื้อ | W29: =IF(T29<=0, "🔴 วิกฤต! (ของหมด)", IF(T29<=S29, "🟡 ควรสั่งซื้อ (ต่ำกว่า ROP)", "🟢 ปกติ")) -> 🔴 วิกฤต! (ของหมด) | X29: 9 | Y29: Maintenance Team | Z29: 0
A30: 29 | B30: Forming | C30: Vacuum | D30: - | F30: A4-A7,B4-B7 | G30: Electrical System | H30: PT-29 | I30: PLC Controller | J30: A | K30: Omron | M30: PCS | N30: 0 | O30: AR-29 | P30: 0 | Q30: 0 | R30: =ROUND(Q30*0.5,0) -> 0 | S30: =Q30+R30 -> 0 | T30: =SUMIF('Stock In Log'!C:C, H30, 'Stock In Log'!D:D) - SUMIF('Stock Out Log'!C:C, H30, 'Stock Out Log'!D:D) -> 0 | U30: =N30*T30 -> 0 | V30: =IF(T30<=0,"ควรสั่งซื้อ", IF(T30<=S30,"ควรสั่งซื้อ","ปกติ")) -> ควรสั่งซื้อ | W30: =IF(T30<=0, "🔴 วิกฤต! (ของหมด)", IF(T30<=S30, "🟡 ควรสั่งซื้อ (ต่ำกว่า ROP)", "🟢 ปกติ")) -> 🔴 วิกฤต! (ของหมด) | X30: 9 | Y30: Maintenance Team | Z30: 0
A31: 30 | B31: Forming | C31: Vacuum | D31: - | F31: A4-A7,B4-B8 | G31: Electrical System | H31: PT-30 | I31: PLC Controller | J31: A | K31: Omron | M31: PCS | N31: 28000 | O31: AR-30 | P31: 0 | Q31: 0 | R31: =ROUND(Q31*0.5,0) -> 0 | S31: =Q31+R31 -> 0 | T31: =SUMIF('Stock In Log'!C:C, H31, 'Stock In Log'!D:D) - SUMIF('Stock Out Log'!C:C, H31, 'Stock Out Log'!D:D) -> 0 | U31: =N31*T31 -> 0 | V31: =IF(T31<=0,"ควรสั่งซื้อ", IF(T31<=S31,"ควรสั่งซื้อ","ปกติ")) -> ควรสั่งซื้อ | W31: =IF(T31<=0, "🔴 วิกฤต! (ของหมด)", IF(T31<=S31, "🟡 ควรสั่งซื้อ (ต่ำกว่า ROP)", "🟢 ปกติ")) -> 🔴 วิกฤต! (ของหมด) | X31: 9 | Y31: Maintenance Team | Z31: 0 | AB31: ศิวจักร์ 3000 บาท ค่าแรง
A32: 31 | B32: Forming | C32: Vacuum | D32: - | F32: A4-A7,B4-B7 | G32: Electrical System | H32: PT-31 | I32: PLC Controller | J32: A | K32: Omron | M32: PCS | N32: 0 | O32: AR-31 | P32: 0 | Q32: 0 | R32: =ROUND(Q32*0.5,0) -> 0 | S32: =Q32+R32 -> 0 | T32: =SUMIF('Stock In Log'!C:C, H32, 'Stock In Log'!D:D) - SUMIF('Stock Out Log'!C:C, H32, 'Stock Out Log'!D:D) -> 0 | U32: =N32*T32 -> 0 | V32: =IF(T32<=0,"ควรสั่งซื้อ", IF(T32<=S32,"ควรสั่งซื้อ","ปกติ")) -> ควรสั่งซื้อ | W32: =IF(T32<=0, "🔴 วิกฤต! (ของหมด)", IF(T32<=S32, "🟡 ควรสั่งซื้อ (ต่ำกว่า ROP)", "🟢 ปกติ")) -> 🔴 วิกฤต! (ของหมด) | X32: 9 | Y32: Maintenance Team | Z32: 0
A33: 32 | B33: Forming | C33: Vacuum | D33: - | F33: A4-A7,B4-B7 | G33: Electrical System | H33: PT-32 | I33: PLC Controller | J33: A | K33: Omron | M33: PCS | N33: 0 | O33: AR-32 | P33: 0 | Q33: 0 | R33: =ROUND(Q33*0.5,0) -> 0 | S33: =Q33+R33 -> 0 | T33: =SUMIF('Stock In Log'!C:C, H33, 'Stock In Log'!D:D) - SUMIF('Stock Out Log'!C:C, H33, 'Stock Out Log'!D:D) -> 0 | U33: =N33*T33 -> 0 | V33: =IF(T33<=0,"ควรสั่งซื้อ", IF(T33<=S33,"ควรสั่งซื้อ","ปกติ")) -> ควรสั่งซื้อ | W33: =IF(T33<=0, "🔴 วิกฤต! (ของหมด)", IF(T33<=S33, "🟡 ควรสั่งซื้อ (ต่ำกว่า ROP)", "🟢 ปกติ")) -> 🔴 วิกฤต! (ของหมด) | X33: 9 | Y33: Maintenance Team | Z33: 0
A34: 33 | B34: Forming | C34: Vacuum | D34: - | F34: All | G34: Electrical System | H34: PT-33 | I34: Touch Screen | J34: B | K34: Fuji | M34: PCS | N34: 0 | O34: AR-33 | P34: 0 | Q34: 0 | R34: =ROUND(Q34*0.5,0) -> 0 | S34: =Q34+R34 -> 0 | T34: =SUMIF('Stock In Log'!C:C, H34, 'Stock In Log'!D:D) - SUMIF('Stock Out Log'!C:C, H34, 'Stock Out Log'!D:D) -> 0 | U34: =N34*T34 -> 0 | V34: =IF(T34<=0,"ควรสั่งซื้อ", IF(T34<=S34,"ควรสั่งซื้อ","ปกติ")) -> ควรสั่งซื้อ | W34: =IF(T34<=0, "🔴 วิกฤต! (ของหมด)", IF(T34<=S34, "🟡 ควรสั่งซื้อ (ต่ำกว่า ROP)", "🟢 ปกติ")) -> 🔴 วิกฤต! (ของหมด) | X34: 6 | Y34: Maintenance Team | Z34: 0
A35: 34 | B35: Forming | C35: Vacuum | D35: - | F35: All | G35: Electrical System | H35: PT-34 | I35: Heater ( Top Plate) | J35: B | K35: Srang Sern | M35: PCS | N35: 0 | O35: AR-34 | P35: 3 | Q35: 2 | R35: =ROUND(Q35*0.5,0) -> 1 | S35: =Q35+R35 -> 3 | T35: =SUMIF('Stock In Log'!C:C, H35, 'Stock In Log'!D:D) - SUMIF('Stock Out Log'!C:C, H35, 'Stock Out Log'!D:D) -> 0 | U35: =N35*T35 -> 0 | V35: =IF(T35<=0,"ควรสั่งซื้อ", IF(T35<=S35,"ควรสั่งซื้อ","ปกติ")) -> ควรสั่งซื้อ | W35: =IF(T35<=0, "🔴 วิกฤต! (ของหมด)", IF(T35<=S35, "🟡 ควรสั่งซื้อ (ต่ำกว่า ROP)", "🟢 ปกติ")) -> 🔴 วิกฤต! (ของหมด) | X35: 6 | Y35: Maintenance Team | Z35: 45 | AA35: oversee
A36: 35 | B36: Forming | C36: Vacuum | D36: - | F36: All | G36: Electrical System | H36: PT-35 | I36: Heater(Top/Lower Plate ) | J36: B | K36: Srang Sern | M36: PCS | N36: 0 | O36: AR-35 | P36: 4 | Q36: 2 | R36: =ROUND(Q36*0.5,0) -> 1 | S36: =Q36+R36 -> 3 | T36: =SUMIF('Stock In Log'!C:C, H36, 'Stock In Log'!D:D) - SUMIF('Stock Out Log'!C:C, H36, 'Stock Out Log'!D:D) -> 1 | U36: =N36*T36 -> 0 | V36: =IF(T36<=0,"ควรสั่งซื้อ", IF(T36<=S36,"ควรสั่งซื้อ","ปกติ")) -> ควรสั่งซื้อ | W36: =IF(T36<=0, "🔴 วิกฤต! (ของหมด)", IF(T36<=S36, "🟡 ควรสั่งซื้อ (ต่ำกว่า ROP)", "🟢 ปกติ")) -> 🟡 ควรสั่งซื้อ (ต่ำกว่า ROP) | X36: 6 | Y36: Maintenance Team | Z36: 45 | AA36: oversee
A37: 36 | B37: Forming | C37: Vacuum | D37: - | F37: All | G37: Electrical System | H37: PT-36 | I37: Heater(Top/Lower Plate) | J37: B | K37: Srang Sern | M37: PCS | N37: 0 | O37: AR-36 | P37: 2 | Q37: 1 | R37: =ROUND(Q37*0.5,0) -> 1 | S37: =Q37+R37 -> 2 | T37: =SUMIF('Stock In Log'!C:C, H37, 'Stock In Log'!D:D) - SUMIF('Stock Out Log'!C:C, H37, 'Stock Out Log'!D:D) -> 1 | U37: =N37*T37 -> 0 | V37: =IF(T37<=0,"ควรสั่งซื้อ", IF(T37<=S37,"ควรสั่งซื้อ","ปกติ")) -> ควรสั่งซื้อ | W37: =IF(T37<=0, "🔴 วิกฤต! (ของหมด)", IF(T37<=S37, "🟡 ควรสั่งซื้อ (ต่ำกว่า ROP)", "🟢 ปกติ")) -> 🟡 ควรสั่งซื้อ (ต่ำกว่า ROP) | X37: 6 | Y37: Maintenance Team | Z37: 45 | AA37: oversee
A38: 37 | B38: Forming | C38: Vacuum | D38: - | F38: All | G38: Electrical System | H38: PT-37 | I38: Heater ( Top Plate) | J38: B | K38: Srang Sern | M38: PCS | N38: 0 | O38: AR-37 | P38: 2 | Q38: 1 | R38: =ROUND(Q38*0.5,0) -> 1 | S38: =Q38+R38 -> 2 | T38: =SUMIF('Stock In Log'!C:C, H38, 'Stock In Log'!D:D) - SUMIF('Stock Out Log'!C:C, H38, 'Stock Out Log'!D:D) -> 5 | U38: =N38*T38 -> 0 | V38: =IF(T38<=0,"ควรสั่งซื้อ", IF(T38<=S38,"ควรสั่งซื้อ","ปกติ")) -> ปกติ | W38: =IF(T38<=0, "🔴 วิกฤต! (ของหมด)", IF(T38<=S38, "🟡 ควรสั่งซื้อ (ต่ำกว่า ROP)", "🟢 ปกติ")) -> 🟢 ปกติ | X38: 6 | Y38: Maintenance Team | Z38: 45 | AA38: oversee
A39: 38 | B39: Forming | C39: Desma | D39: - | F39: D8,D10,D11 | G39: Top HEPL part | H39: PT-38 | I39: Insulating plate top 560 x630 S400HT | J39: B | K39: Desma | M39: PCS | N39: 12271 | O39: AR-38 | P39: 2 | Q39: 1 | R39: =ROUND(Q39*0.5,0) -> 1 | S39: =Q39+R39 -> 2 | T39: =SUMIF('Stock In Log'!C:C, H39, 'Stock In Log'!D:D) - SUMIF('Stock Out Log'!C:C, H39, 'Stock Out Log'!D:D) -> 0 | U39: =N39*T39 -> 0 | V39: =IF(T39<=0,"ควรสั่งซื้อ", IF(T39<=S39,"ควรสั่งซื้อ","ปกติ")) -> ควรสั่งซื้อ | W39: =IF(T39<=0, "🔴 วิกฤต! (ของหมด)", IF(T39<=S39, "🟡 ควรสั่งซื้อ (ต่ำกว่า ROP)", "🟢 ปกติ")) -> 🔴 วิกฤต! (ของหมด) | X39: 6 | Y39: Maintenance Team | Z39: 0 | AA39: oversee
A40: 39 | B40: Forming | C40: Desma | D40: - | F40: D8,D10,D11 | G40: Top HEPL part | H40: PT-39 | I40: Socket Head Screw M16x75 DiN 921-8.8 | J40: B | K40: Desma | M40: PCS | N40: 36.85 | O40: AR-39 | P40: 20 | Q40: 12 | R40: =ROUND(Q40*0.5,0) -> 6 | S40: =Q40+R40 -> 18 | T40: =SUMIF('Stock In Log'!C:C, H40, 'Stock In Log'!D:D) - SUMIF('Stock Out Log'!C:C, H40, 'Stock Out Log'!D:D) -> 0 | U40: =N40*T40 -> 0 | V40: =IF(T40<=0,"ควรสั่งซื้อ", IF(T40<=S40,"ควรสั่งซื้อ","ปกติ")) -> ควรสั่งซื้อ | W40: =IF(T40<=0, "🔴 วิกฤต! (ของหมด)", IF(T40<=S40, "🟡 ควรสั่งซื้อ (ต่ำกว่า ROP)", "🟢 ปกติ")) -> 🔴 วิกฤต! (ของหมด) | X40: 6 | Y40: Maintenance Team | Z40: 0 | AA40: oversee
...

Sheet Stock In Log
A1: Date | B1: Doc No. | C1: Part Code | D1: Qty In | E1: Receiver
A2: 2026-05-01 | B2: INIT-001 | C2: PT-01 | D2: 2 | E2: Store_Admin
A3: 2026-05-01 | B3: INIT-001 | C3: PT-02 | D3: 2 | E3: Store_Admin
A4: 2026-05-01 | B4: INIT-001 | C4: PT-03 | D4: 2 | E4: Store_Admin
A5: 2026-05-01 | B5: INIT-001 | C5: PT-04 | D5: 2 | E5: Store_Admin
A6: 2026-05-01 | B6: INIT-001 | C6: PT-05 | D6: 3 | E6: Store_Admin
A7: 2026-05-01 | B7: INIT-001 | C7: PT-06 | D7: 3 | E7: Store_Admin
A8: 2026-05-01 | B8: INIT-001 | C8: PT-07 | D8: 2 | E8: Store_Admin
A9: 2026-05-01 | B9: INIT-001 | C9: PT-08 | D9: 2 | E9: Store_Admin
A10: 2026-05-01 | B10: INIT-001 | C10: PT-09 | D10: 2 | E10: Store_Admin
A11: 2026-05-01 | B11: INIT-001 | C11: PT-10 | D11: 2 | E11: Store_Admin
A12: 2026-05-01 | B12: INIT-001 | C12: PT-11 | D12: 2 | E12: Store_Admin
A13: 2026-05-01 | B13: INIT-001 | C13: PT-12 | D13: 2 | E13: Store_Admin
... A74: 2026-05-01 | B74: INIT-001 | C74: PT-73 | D74: 2 | E74: Store_Admin

Sheet Stock Out Log
A1: Date | B1: Doc No. | C1: Part Code | D1: Qty Out | E1: Requester | F1: Machine Code | G1: Reason
A2: 2026-05-12 | B2: REQ-2026001 | C2: PT-01 | D2: 2 | E2: ช่างสมชาย | F2: C16 | G2: อะไหล่เสื่อมสภาพตามรอบการใช้งาน (PM)
A3: 2026-05-12 | B3: REQ-2026001 | C3: PT-02 | D3: 2 | E3: ช่างสมชาย | F3: B17 | G3: อะไหล่เสื่อมสภาพตามรอบการใช้งาน (PM)
A4: 2026-05-12 | B4: REQ-2026001 | C4: PT-03 | D4: 2 | E4: ช่างสมชาย | F4: B17 | G4: อะไหล่เสื่อมสภาพตามรอบการใช้งาน (PM)
A5: 2026-05-12 | B5: REQ-2026001 | C5: PT-04 | D5: 2 | E5: ช่างสมชาย | F5: - | G5: อะไหล่เสื่อมสภาพตามรอบการใช้งาน (PM)
A6: 2026-05-12 | B6: REQ-2026001 | C6: PT-05 | D6: 2 | E6: ช่างสมชาย | F6: - | G6: อะไหล่เสื่อมสภาพตามรอบการใช้งาน (PM)
A7: 2026-05-12 | B7: REQ-2026001 | C7: PT-06 | D7: 2 | E7: ช่างสมชาย | F7: - | G7: อะไหล่เสื่อมสภาพตามรอบการใช้งาน (PM)
A8: 2026-05-12 | B8: REQ-2026001 | C8: PT-07 | D8: 2 | E8: ช่างสมชาย | F8: - | G8: อะไหล่เสื่อมสภาพตามรอบการใช้งาน (PM)
A9: 2026-05-12 | B9: REQ-2026001 | C9: PT-08 | D9: 2 | E9: ช่างสมชาย | F9: - | G9: อะไหล่เสื่อมสภาพตามรอบการใช้งาน (PM)
A10: 2026-05-12 | B10: REQ-2026001 | C10: PT-09 | D10: 2 | E10: ช่างสมชาย | F10: - | G10: อะไหล่เสื่อมสภาพตามรอบการใช้งาน (PM)
A11: 2026-05-12 | B11: REQ-2026001 | C11: PT-10 | D11: 2 | E11: ช่างสมชาย | F11: - | G11: อะไหล่เสื่อมสภาพตามรอบการใช้งาน (PM)
A12: 2026-05-12 | B12: REQ-2026001 | C12: PT-11 | D12: 2 | E12: ช่างสมชาย | F12: - | G12: อะไหล่เสื่อมสภาพตามรอบการใช้งาน (PM)
A13: 2026-05-12 | B13: REQ-2026001 | C13: PT-12 | D13: 2 | E13: ช่างสมชาย | F13: - | G13: อะไหล่เสื่อมสภาพตามรอบการใช้งาน (PM)
... A74: 2026-05-12 | B74: REQ-2026001 | C74: PT-73 | D74: 2 | E74: ช่างสมชาย | F74: EX-01 | G74: อะไหล่เสื่อมสภาพตามรอบการใช้งาน (PM)

Sheet Improvement_Recom
A1: Machine Spare Part Control - Improvement Recommendation
A3: Area | B3: Current Situation | C3: Gap / Weakness | D3: Recommended Improvement | E3: Benefit | F3: Priority | G3: Owner | H3: Timeline
A4: Master Data | B4: ยังไม่มี Machine Criticality Score | C4: วัดความเสี่ยงเครื่องจักรไม่แม่น | D4: เพิ่มคะแนน Criticality ตาม Production Impact / Safety / Quality | E4: จัดลำดับการถือ Stock ได้แม่นขึ้น | F4: High | G4: Maintenance | H4: 1 Month
A5: Inventory Control | B5: มี Min-Max แต่ยังไม่มี Safety Stock | C5: เสี่ยง Stock Out | D5: เพิ่มสูตร Safety Stock และ ROP | E5: ลด Emergency Purchase | F5: High | G5: Store + Purchasing | H5: 2 Weeks
A6: Dashboard | B6: มี KPI พื้นฐาน | C6: ยังไม่มี Pareto และ Trend | D6: เพิ่ม Pareto Top Failure และ Monthly Trend | E6: ผู้บริหารเห็นปัญหาหลักทันที | F6: High | G6: Engineering | H6: 1 Month
A7: Breakdown Analysis | B7: มี Breakdown History | C7: ยังไม่วิเคราะห์ MTBF/MTTR | D7: เพิ่ม MTBF และ MTTR Dashboard | E7: วิเคราะห์ Reliability ได้ | F7: Medium | G7: Maintenance | H7: 1 Month
A8: Dead Stock | B8: มี Aging | C8: ยังไม่มี Cost Impact | D8: เพิ่ม Dead Stock Cost Summary | E8: ลดทุนจม | F8: High | G8: Store | H8: 2 Weeks
A9: Supplier Control | B9: มี Supplier Name | C9: ยังไม่มี Supplier KPI | D9: เพิ่ม On-Time Delivery และ Quality KPI | E9: ประเมิน Vendor ได้ | F9: Medium | G9: Purchasing | H9: 1 Month
A10: PM Planning | B10: มี PM Schedule | C10: ยังไม่เชื่อม Spare Usage | D10: เชื่อม PM กับ Spare Consumption | E10: Forecast อะไหล่ได้แม่นขึ้น | F10: High | G10: Maintenance | H10: 1 Month
A11: Presentation | B11: ยังไม่มี Executive Summary | C11: ผู้บริหารดูข้อมูลยาก | D11: เพิ่มหน้า Summary Dashboard 1 Page | E11: ใช้ Present ผู้บริหารได้ทันที | F11: Critical | G11: Engineering | H11: 1 Week
B22: Machine Criticality Score
B23: คะแนน 9 (วิกฤตสูงสุด)
B24: คะแนน 6 (ความเสี่ยงปานกลาง-สูง)
B25: คะแนน 3 (ความเสี่ยงต่ำ)

Sheet Presentation_Guide
A1: Presentation Structure Recommendation
A3: Slide 1 | B3: Current Spare Part Situation | C3: แสดงปัญหา Overstock / Breakdown / Emergency Purchase
A4: Slide 2 | B4: Criticality Matrix | C4: แสดง Machine Rank vs Part Rank
A5: Slide 3 | B5: Current Inventory KPI | C5: Inventory Accuracy / Dead Stock / Reorder
A6: Slide 4 | B6: Top Breakdown Analysis | C6: Pareto Top Failure Part
A7: Slide 5 | B7: Dead Stock Cost | C7: มูลค่าของค้างคลัง
A8: Slide 6 | B8: Improvement Plan | C8: Action Plan + Timeline
A9: Slide 7 | B9: Expected Benefit | C9: ลด Downtime / ลด Stock / ลด Cost

Sheet Executive_Dashboard
A1: Machine Spare Part Executive Dashboard
A3: KPI | B3: Target | C3: Actual | D3: Status
A4: Inventory Accuracy % | B4: 98 | C4: 96 | D4: Below Target
A5: Critical Part Availability % | B5: 100 | C5: 95 | D5: Critical
A6: Dead Stock Value | B6: 50000 | C6: 145000 | D6: High
A7: Emergency Purchase % | B7: 5 | C7: 8 | D7: High
A12: MC Group Summary + Risk Zone
A14: MC Group | B14: Machine Count | C14: Spare Part Qty | D14: Inventory Value (THB) | E14: Critical Parts | F14: Reorder Items | G14: Risk Zone
A15: Compression | B15: 12 | C15: 320 | D15: 1250000 | E15: 48 | F15: 12 | G15: HIGH RISK
A16: Injection | B16: 8 | C16: 240 | D16: 980000 | E16: 35 | F16: 8 | G16: HIGH RISK
A17: Vacuum | B17: 5 | C17: 120 | D17: 450000 | E17: 15 | F17: 3 | G17: MEDIUM RISK
A18: CNC | B18: 4 | C18: 90 | D18: 780000 | E18: 18 | F18: 5 | G18: MEDIUM RISK
A19: Utility | B19: 10 | C19: 150 | D19: 220000 | E19: 5 | F19: 1 | G19: LOW RISK
A25: Risk Zone | B25: Count
A26: HIGH | B26: 2
A27: MEDIUM | B27: 2
A28: LOW | B28: 1
A40: Executive Key Focus
A42: 1. Compression และ Injection มีความเสี่ยงสูงสุด
A43: 2. Critical Part ต้อง Maintain Safety Stock
A44: 3. Dead Stock สูงเกิน Target
A45: 4. ควรลด Emergency Purchase และติดตาม Supplier Lead Time
